# 并发运行任务
## awaitable asyncio.gather(*aws, loop=None, return_exceptions=False)
并发 运行 aws 序列中的 可等待对象。

如果 aws 中的某个可等待对象为协程，它将自动作为一个任务加入日程。

如果所有可等待对象都成功完成，结果将是一个由所有返回值聚合而成的列表。结果值的顺序与 aws 中可等待对象的顺序一致。

如果 return_exceptions 为 False (默认)，所引发的首个异常会立即传播给等待 gather() 的任务。aws 序列中的其他可等待对象 不会被取消 并将继续运行。

如果 return_exceptions 为 True，异常会和成功的结果一样处理，并聚合至结果列表。

如果 gather() 被取消，所有被提交 (尚未完成) 的可等待对象也会 被取消。

如果 aws 序列中的任一 Task 或 Future 对象 被取消，它将被当作引发了 CancelledError 一样处理 -- 在此情况下 gather() 调用 不会 被取消。这是为了防止一个已提交的 Task/Future 被取消导致其他 Tasks/Future 也被取消。

示例:
```
import asyncio

async def factorial(name, number):
    f = 1
    for i in range(2, number + 1):
        print(f"Task {name}: Compute factorial({i})...")
        await asyncio.sleep(1)
        f *= i
    print(f"Task {name}: factorial({number}) = {f}")

async def main():
    # Schedule three calls *concurrently*:
    await asyncio.gather(
        factorial("A", 2),
        factorial("B", 3),
        factorial("C", 4),
    )

asyncio.run(main())

# Expected output:
#
#     Task A: Compute factorial(2)...
#     Task B: Compute factorial(2)...
#     Task C: Compute factorial(2)...
#     Task A: factorial(2) = 2
#     Task B: Compute factorial(3)...
#     Task C: Compute factorial(3)...
#     Task B: factorial(3) = 6
#     Task C: Compute factorial(4)...
#     Task C: factorial(4) = 24
```
在 3.7 版更改: 如果 gather 本身被取消，则无论 return_exceptions 取值为何，消息都会被传播。